Workbook

Sheet combined_protein_level
A1: precursor_protein | B1: mismatch_precursor_id_number | C1: mismatch_evidence_peptides_scans | D1: mismatch_n_noncontained_le9 | E1: matched_precursor_id_number | F1: matched_evidence_peptides_scans | G1: matched_n_noncontained_le9 | H1: evidence_peptides_scans | I1: combined_n_noncontained_le9 | J1: In_2.1.22-only
A2: O60330 | B2: 28 | C2: [('GQVICFIQGNLPFK', 2375, 'lost_3_aa_Nterm', True, 'Missed'), ('GQVICFIQGNLPFK', 2374, 'lost_3_aa_Nterm', True, 'Missed'), ('GQVICFIQGNLPFK', 2379, 'lost_3_aa_Nterm', True, 'Missed'), ('GQVICFIQGNLPFK', 2377, 'lost_3_aa_Nterm', True, 'Missed'), ('GQVICFIQGNLPFK', 2378, 'lost_3_aa_Nterm', True, 'Missed'), ('GQVICFIQGNLPFK', 2376, 'lost_3_aa_Nterm', True, 'Missed'), ('NGQVICFIQGNLPFK', 2397, 'lost_3_aa_Nterm', False, 'Missed'), ('NGQVICFIQGNLPFK', 2398, 'lost_3_aa_Nterm', False, 'Missed'), ('NGQVICFIQGNLPFK', 2395, 'lost_3_aa_Nterm', False, 'Missed'), ('NGQVICFIQGNLPFK', 2396, 'lost_3_aa_Nterm', False, 'Missed'), ('TQIRYSVPEELEKG', 2412, 'IDENTIFIED', True, 'Missed'), ('YVDDKAAQVF', 2423, 'HLA1', True, 'Missed'), ('IVQNGADGSKY', 2322, 'IDENTIFIED', True, 'Missed'), ('NGQVICFIQGNLPFK', 2399, 'lost_3_aa_Nterm', False, 'Missed'), ('IVQNGADGSKY', 2323, 'IDENTIFIED', True, 'Missed'), ('SSFDYEQFRDLQVK', 2307, 'IDENTIFIED', True, 'Missed'), ('IVQNGADGSKY', 2324, 'IDENTIFIED', True, 'Missed'), ('LLQASGGGLTGAPASHFVGVDGVQAFLQTYSHEVSLTTDSR', 2334, 'peptide_length_>_40', True, 'Missed'), ('LLQASGGGLTGAPASHFVGVDGVQAFLQTYSHEVSLTTDSR', 2330, 'peptide_length_>_40', True, 'Missed'), ('AQPEYRASVPENLALG', 2318, 'IDENTIFIED', True, 'Missed'), ('LLQASGGGLTGAPASHFVGVDGVQAFLQTYSHEVSLTTDSR', 2337, 'peptide_length_>_40', True, 'Missed'), ('LLQASGGGLTGAPASHFVGVDGVQAFLQTYSHEVSLTTDSR', 2331, 'peptide_length_>_40', True, 'Missed'), ('LLQASGGGLTGAPASHFVGVDGVQAFLQTYSHEVSLTTDSR', 2338, 'peptide_length_>_40', True, 'Missed'), ('LLQASGGGLTGAPASHFVGVDGVQAFLQTYSHEVSLTTDSR', 2336, 'peptide_length_>_40', True, 'Missed'), ('LLQASGGGLTGAPASHFVGVDGVQAFLQTYSHEVSLTTDSR', 2333, 'peptide_length_>_40', True, 'Missed'), ('LLQASGGGLTGAPASHFVGVDGVQAFLQTYSHEVSLTTDSR', 2335, 'peptide_length_>_40', True, 'Missed'), ('LLQASGGGLTGAPASHFVGVDGVQAFLQTYSHEVSLTTDSR', 2332, 'peptide_length_>_40', True, 'Missed'), ('LLQASGGGLTGAPASHFVGVDGVQAFLQTYSHEVSLTTDSR', 2339, 'peptide_length_>_40', True, 'Missed')] | D2: 7 | E2: 98 | F2: [('VMVLDANDNAPAFAQPEYR', 2345, nan, True, 'Matched'), ('ALSSFDYEQFRDLQ', 2380, nan, False, 'Matched'), ('ALSSFDYEQFRDLQ', 2382, nan, False, 'Matched'), ('LSSFDYEQFRDLQV', 2394, nan, False, 'Matched'), ('ALSSFDYEQFRDLQ', 2383, nan, False, 'Matched'), ('IVQNGADGSKY', 2325, nan, True, 'Matched'), ('SSFDYEQFRDLQVK', 2303, nan, False, 'Matched'), ('ALSSFDYEQFRDLQ', 2381, nan, False, 'Matched'), ('LSSFDYEQFRDLQ', 2349, nan, True, 'Matched'), ('LSSFDYEQFRDLQV', 2391, nan, False, 'Matched'), ('LSSFDYEQFRDLQV', 2392, nan, False, 'Matched'), ('LSSFDYEQFRDLQ', 2346, nan, True, 'Matched'), ('IVQNGADGSKY', 2326, nan, True, 'Matched'), ('LSSFDYEQFRDLQ', 2348, nan, True, 'Matched'), ('IVQNGADGSKY', 2327, nan, True, 'Matched'), ('LSSFDYEQFRDLQV', 2390, nan, False, 'Matched'), ('DYEQFRDLQVK', 2419, nan, True, 'Matched'), ('LSSFDYEQFRDLQ', 2350, nan, True, 'Matched'), ('IVQNGADGSKY', 2329, nan, True, 'Matched'), ('SYGNYYSLVTDIVLDR', 2401, nan, True, 'Matched'), ('SSFDYEQFRDLQVK', 2301, nan, False, 'Matched'), ('LSSFDYEQFRDLQ', 2347, nan, True, 'Matched'), ('SSFDYEQFRDLQVK', 2299, nan, False, 'Matched'), ('SYGNYYSLVTDIVLDR', 2402, nan, True, 'Matched'), ('SYGNYYSLVTDIVLDR', 2400, nan, True, 'Matched'), ('SSFDYEQFRDLQVK', 2302, nan, False, 'Matched'), ('NSLQSYELSPNTHFSLIVQNGADGSK', 2420, nan, True, 'Matched'), ('TQIRYSVPEELEKG', 2410, nan, True, 'Matched'), ('SEPLLLSGDSVFSK', 2369, nan, True, 'Matched'), ('YSFRYVDDKAAQVFK', 2422, nan, True, 'Matched'), ('YALSSFDYEQFRDLQVK', 2359, nan, False, 'Matched'), ('TQIRYSVPEELEKG', 2409, nan, True, 'Matched'), ('DSHGLIEQAPPNTDWR', 2366, nan, True, 'Matched'), ('LSSFDYEQFRDLQV', 2393, nan, False, 'Matched'), ('DSHGLIEQAPPNTDWR', 2364, nan, True, 'Matched'), ('YALSSFDYEQFRDLQVK', 2355, nan, False, 'Matched'), ('YALSSFDYEQFRDLQVK', 2357, nan, False, 'Matched'), ('YALSSFDYEQFRDLQVK', 2358, nan, False, 'Matched'), ('FPLPHAWDPDIGK', 2368, nan, True, 'Matched'), ('SEPLLLSGDSVFSK', 2372, nan, True, 'Matched'), ('YALSSFDYEQFRDLQVK', 2356, nan, False, 'Matched'), ('DSHGLIEQAPPNTDWR', 2363, nan, True, 'Matched'), ('ALSSFDYEQFRDLQ', 2384, nan, False, 'Matched'), ('SYGNYYSLVTDIVLDR', 2403, nan, True, 'Matched'), ('FPLPHAWDPDIGK', 2367, nan, True, 'Matched'), ('SEPLLLSGDSVFSK', 2370, nan, True, 'Matched'), ('LSSFDYEQFRDLQ', 2353, nan, True, 'Matched'), ('SHLIFPQPNYADMLVSQESFEK', 2298, nan, True, 'Matched'), ('AAHHLVLTASDGGDPVR', 2404, nan, True, 'Matched'), ('SSFDYEQFRDLQVK', 2308, nan, False, 'Matched'), ('SSFDYEQFRDLQVK', 2300, nan, False, 'Matched'), ('SSFDYEQFRDLQVK', 2309, nan, False, 'Matched'), ('YALSSFDYEQFRDLQVK', 2360, nan, False, 'Matched'), ('SSFDYEQFRDLQVK', 2306, nan, False, 'Matched'), ('IDREELCMGAIK', 2413, nan, True, 'Matched'), ('YALSSFDYEQFRDLQVK', 2361, nan, False, 'Matched'), ('LSSFDYEQFRDLQ', 2351, nan, True, 'Matched'), ('CQLNLDILMEDK', 2418, nan, True, 'Matched'), ('LEIKISENAATEMR', 2415, nan, True, 'Matched'), ('VMVLDANDNAPAFAQPEYR', 2342, nan, True, 'Matched'), ('VMVLDANDNAPAFAQPEYR', 2341, nan, True, 'Matched'), ('SSFDYEQFRDLQVK', 2305, nan, False, 'Matched'), ('LSSFDYEQFRDLQ', 2352, nan, True, 'Matched'), ('LEIKISENAATEMRFP', 2417, nan, False, 'Matched'), ('IVQNGADGSKY', 2321, nan, True, 'Matched'), ('IVQNGADGSKY', 2320, nan, True, 'Matched'), ('SSFDYEQFRDLQVK', 2304, nan, False, 'Matched'), ('LEIKISENAATEMR', 2414, nan, True, 'Matched'), ('SEPLLLSGDSVFSK', 2371, nan, True, 'Matched'), ('LSSFDYEQFRDLQ', 2354, nan, True, 'Matched'), ('LEIKISENAATEMRFP', 2416, nan, False, 'Matched'), ('TQIRYSVPEELEKG', 2411, nan, True, 'Matched'), ('FAQPEYRASVPENLALG', 2387, nan, False, 'Matched'), ('AQPEYRASVPENLAL', 2405, nan, True, 'Matched'), ('SEPLLLSGDSVFSK', 2373, nan, True, 'Matched'), ('VMVLDANDNAPAFAQPEYR', 2343, nan, True, 'Matched'), ('VMVLDANDNAPAFAQPEYR', 2340, nan, True, 'Matched'), ('VDGVQAFLQTYSHEVSLTTDSR', 2421, nan, True, 'Matched'), ('AQPEYRASVPENLALG', 2310, nan, False, 'Matched'), ('FAQPEYRASVPENLALG', 2389, nan, False, 'Matched'), ('IVQNGADGSKY', 2328, nan, True, 'Matched'), ('AQPEYRASVPENLALG', 2312, nan, False, 'Matched'), ('AQPEYRASVPENLALG', 2311, nan, False, 'Matched'), ('AQPEYRASVPENLAL', 2407, nan, True, 'Matched'), ('DSHGLIEQAPPNTDWR', 2365, nan, True, 'Matched'), ('AQPEYRASVPENLALG', 2314, nan, False, 'Matched'), ('AQPEYRASVPENLALG', 2313, nan, False, 'Matched'), ('VMVLDANDNAPAFAQPEYR', 2344, nan, True, 'Matched'), ('AQPEYRASVPENLALG', 2315, nan, False, 'Matched'), ('AQPEYRASVPENLALG', 2317, nan, False, 'Matched'), ('YALSSFDYEQFRDLQVK', 2362, nan, False, 'Matched'), ('AQPEYRASVPENLAL', 2408, nan, True, 'Matched'), ('AQPEYRASVPENLALG', 2319, nan, False, 'Matched'), ('FAQPEYRASVPENLALG', 2388, nan, False, 'Matched'), ('AQPEYRASVPENLAL', 2406, nan, True, 'Matched'), ('AQPEYRASVPENLALG', 2316, nan, False, 'Matched'), ('FAQPEYRASVPENLALG', 2385, nan, False, 'Matched'), ('FAQPEYRASVPENLALG', 2386, nan, False, 'Matched')] | G2: 18 | H2: [('GQVICFIQGNLPFK', 2375, 'lost_3_aa_Nterm', True, 'Missed'), ('GQVICFIQGNLPFK', 2374, 'lost_3_aa_Nterm', True, 'Missed'), ('GQVICFIQGNLPFK', 2379, 'lost_3_aa_Nterm', True, 'Missed'), ('GQVICFIQGNLPFK', 2377, 'lost_3_aa_Nterm', True, 'Missed'), ('GQVICFIQGNLPFK', 2378, 'lost_3_aa_Nterm', True, 'Missed'), ('GQVICFIQGNLPFK', 2376, 'lost_3_aa_Nterm', True, 'Missed'), ('NGQVICFIQGNLPFK', 2397, 'lost_3_aa_Nterm', False, 'Missed'), ('NGQVICFIQGNLPFK', 2398, 'lost_3_aa_Nterm', False, 'Missed'), ('NGQVICFIQGNLPFK', 2395, 'lost_3_aa_Nterm', False, 'Missed'), ('NGQVICFIQGNLPFK', 2396, 'lost_3_aa_Nterm', False, 'Missed'), ('TQIRYSVPEELEKG', 2412, 'IDENTIFIED', True, 'Missed'), ('YVDDKAAQVF', 2423, 'HLA1', True, 'Missed'), ('IVQNGADGSKY', 2322, 'IDENTIFIED', True, 'Missed'), ('NGQVICFIQGNLPFK', 2399, 'lost_3_aa_Nterm', False, 'Missed'), ('IVQNGADGSKY', 2323, 'IDENTIFIED', True, 'Missed'), ('SSFDYEQFRDLQVK', 2307, 'IDENTIFIED', False, 'Missed'), ('IVQNGADGSKY', 2324, 'IDENTIFIED', True, 'Missed'), ('LLQASGGGLTGAPASHFVGVDGVQAFLQTYSHEVSLTTDSR', 2334, 'peptide_length_>_40', False, 'Missed'), ('LLQASGGGLTGAPASHFVGVDGVQAFLQTYSHEVSLTTDSR', 2330, 'peptide_length_>_40', False, 'Missed'), ('AQPEYRASVPENLALG', 2318, 'IDENTIFIED', False, 'Missed'), ('LLQASGGGLTGAPASHFVGVDGVQAFLQTYSHEVSLTTDSR', 2337, 'peptide_length_>_40', False, 'Missed'), ('LLQASGGGLTGAPASHFVGVDGVQAFLQTYSHEVSLTTDSR', 2331, 'peptide_length_>_40', False, 'Missed'), ('LLQASGGGLTGAPASHFVGVDGVQAFLQTYSHEVSLTTDSR', 2338, 'peptide_length_>_40', False, 'Missed'), ('LLQASGGGLTGAPASHFVGVDGVQAFLQTYSHEVSLTTDSR', 2336, 'peptide_length_>_40', False, 'Missed'), ('LLQASGGGLTGAPASHFVGVDGVQAFLQTYSHEVSLTTDSR', 2333, 'peptide_length_>_40', False, 'Missed'), ('LLQASGGGLTGAPASHFVGVDGVQAFLQTYSHEVSLTTDSR', 2335, 'peptide_length_>_40', False, 'Missed'), ('LLQASGGGLTGAPASHFVGVDGVQAFLQTYSHEVSLTTDSR', 2332, 'peptide_length_>_40', False, 'Missed'), ('LLQASGGGLTGAPASHFVGVDGVQAFLQTYSHEVSLTTDSR', 2339, 'peptide_length_>_40', False, 'Missed'), ('VMVLDANDNAPAFAQPEYR', 2345, nan, True, 'Matched'), ('ALSSFDYEQFRDLQ', 2380, nan, False, 'Matched'), ('ALSSFDYEQFRDLQ', 2382, nan, False, 'Matched'), ('LSSFDYEQFRDLQV', 2394, nan, False, 'Matched'), ('ALSSFDYEQFRDLQ', 2383, nan, False, 'Matched'), ('IVQNGADGSKY', 2325, nan, True, 'Matched'), ('SSFDYEQFRDLQVK', 2303, nan, False, 'Matched'), ('ALSSFDYEQFRDLQ', 2381, nan, False, 'Matched'), ('LSSFDYEQFRDLQ', 2349, nan, True, 'Matched'), ('LSSFDYEQFRDLQV', 2391, nan, False, 'Matched'), ('LSSFDYEQFRDLQV', 2392, nan, False, 'Matched'), ('LSSFDYEQFRDLQ', 2346, nan, True, 'Matched'), ('IVQNGADGSKY', 2326, nan, True, 'Matched'), ('LSSFDYEQFRDLQ', 2348, nan, True, 'Matched'), ('IVQNGADGSKY', 2327, nan, True, 'Matched'), ('LSSFDYEQFRDLQV', 2390, nan, False, 'Matched'), ('DYEQFRDLQVK', 2419, nan, True, 'Matched'), ('LSSFDYEQFRDLQ', 2350, nan, True, 'Matched'), ('IVQNGADGSKY', 2329, nan, True, 'Matched'), ('SYGNYYSLVTDIVLDR', 2401, nan, True, 'Matched'), ('SSFDYEQFRDLQVK', 2301, nan, False, 'Matched'), ('LSSFDYEQFRDLQ', 2347, nan, True, 'Matched'), ('SSFDYEQFRDLQVK', 2299, nan, False, 'Matched'), ('SYGNYYSLVTDIVLDR', 2402, nan, True, 'Matched'), ('SYGNYYSLVTDIVLDR', 2400, nan, True, 'Matched'), ('SSFDYEQFRDLQVK', 2302, nan, False, 'Matched'), ('NSLQSYELSPNTHFSLIVQNGADGSK', 2420, nan, True, 'Matched'), ('TQIRYSVPEELEKG', 2410, nan, True, 'Matched'), ('SEPLLLSGDSVFSK', 2369, nan, True, 'Matched'), ('YSFRYVDDKAAQVFK', 2422, nan, False, 'Matched'), ('YALSSFDYEQFRDLQVK', 2359, nan, False, 'Matched'), ('TQIRYSVPEELEKG', 2409, nan, True, 'Matched'), ('DSHGLIEQAPPNTDWR', 2366, nan, True, 'Matched'), ('LSSFDYEQFRDLQV', 2393, nan, False, 'Matched'), ('DSHGLIEQAPPNTDWR', 2364, nan, True, 'Matched'), ('YALSSFDYEQFRDLQVK', 2355, nan, False, 'Matched'), ('YALSSFDYEQFRDLQVK', 2357, nan, False, 'Matched'), ('YALSSFDYEQFRDLQVK', 2358, nan, False, 'Matched'), ('FPLPHAWDPDIGK', 2368, nan, True, 'Matched'), ('SEPLLLSGDSVFSK', 2372, nan, True, 'Matched'), ('YALSSFDYEQFRDLQVK', 2356, nan, False, 'Matched'), ('DSHGLIEQAPPNTDWR', 2363, nan, True, 'Matched'), ('ALSSFDYEQFRDLQ', 2384, nan, False, 'Matched'), ('SYGNYYSLVTDIVLDR', 2403, nan, True, 'Matched'), ('FPLPHAWDPDIGK', 2367, nan, True, 'Matched'), ('SEPLLLSGDSVFSK', 2370, nan, True, 'Matched'), ('LSSFDYEQFRDLQ', 2353, nan, True, 'Matched'), ('SHLIFPQPNYADMLVSQESFEK', 2298, nan, True, 'Matched'), ('AAHHLVLTASDGGDPVR', 2404, nan, True, 'Matched'), ('SSFDYEQFRDLQVK', 2308, nan, False, 'Matched'), ('SSFDYEQFRDLQVK', 2300, nan, False, 'Matched'), ('SSFDYEQFRDLQVK', 2309, nan, False, 'Matched'), ('YALSSFDYEQFRDLQVK', 2360, nan, False, 'Matched'), ('SSFDYEQFRDLQVK', 2306, nan, False, 'Matched'), ('IDREELCMGAIK', 2413, nan, True, 'Matched'), ('YALSSFDYEQFRDLQVK', 2361, nan, False, 'Matched'), ('LSSFDYEQFRDLQ', 2351, nan, True, 'Matched'), ('CQLNLDILMEDK', 2418, nan, True, 'Matched'), ('LEIKISENAATEMR', 2415, nan, True, 'Matched'), ('VMVLDANDNAPAFAQPEYR', 2342, nan, True, 'Matched'), ('VMVLDANDNAPAFAQPEYR', 2341, nan, True, 'Matched'), ('SSFDYEQFRDLQVK', 2305, nan, False, 'Matched'), ('LSSFDYEQFRDLQ', 2352, nan, True, 'Matched'), ('LEIKISENAATEMRFP', 2417, nan, False, 'Matched'), ('IVQNGADGSKY', 2321, nan, True, 'Matched'), ('IVQNGADGSKY', 2320, nan, True, 'Matched'), ('SSFDYEQFRDLQVK', 2304, nan, False, 'Matched'), ('LEIKISENAATEMR', 2414, nan, True, 'Matched'), ('SEPLLLSGDSVFSK', 2371, nan, True, 'Matched'), ('LSSFDYEQFRDLQ', 2354, nan, True, 'Matched'), ('LEIKISENAATEMRFP', 2416, nan, False, 'Matched'), ('TQIRYSVPEELEKG', 2411, nan, True, 'Matched'), ('FAQPEYRASVPENLALG', 2387, nan, False, 'Matched'), ('AQPEYRASVPENLAL', 2405, nan, True, 'Matched'), ('SEPLLLSGDSVFSK', 2373, nan, True, 'Matched'), ('VMVLDANDNAPAFAQPEYR', 2343, nan, True, 'Matched'), ('VMVLDANDNAPAFAQPEYR', 2340, nan, True, 'Matched'), ('VDGVQAFLQTYSHEVSLTTDSR', 2421, nan, True, 'Matched'), ('AQPEYRASVPENLALG', 2310, nan, False, 'Matched'), ('FAQPEYRASVPENLALG', 2389, nan, False, 'Matched'), ('IVQNGADGSKY', 2328, nan, True, 'Matched'), ('AQPEYRASVPENLALG', 2312, nan, False, 'Matched'), ('AQPEYRASVPENLALG', 2311, nan, False, 'Matched'), ('AQPEYRASVPENLAL', 2407, nan, True, 'Matched'), ('DSHGLIEQAPPNTDWR', 2365, nan, True, 'Matched'), ('AQPEYRASVPENLALG', 2314, nan, False, 'Matched'), ('AQPEYRASVPENLALG', 2313, nan, False, 'Matched'), ('VMVLDANDNAPAFAQPEYR', 2344, nan, True, 'Matched'), ('AQPEYRASVPENLALG', 2315, nan, False, 'Matched'), ('AQPEYRASVPENLALG', 2317, nan, False, 'Matched'), ('YALSSFDYEQFRDLQVK', 2362, nan, False, 'Matched'), ('AQPEYRASVPENLAL', 2408, nan, True, 'Matched'), ('AQPEYRASVPENLALG', 2319, nan, False, 'Matched'), ('FAQPEYRASVPENLALG', 2388, nan, False, 'Matched'), ('AQPEYRASVPENLAL', 2406, nan, True, 'Matched'), ('AQPEYRASVPENLALG', 2316, nan, False, 'Matched'), ('FAQPEYRASVPENLALG', 2385, nan, False, 'Matched'), ('FAQPEYRASVPENLALG', 2386, nan, False, 'Matched')] | I2: 19 | J2: =IFERROR(VLOOKUP(A2,dbg_proteins!$A$2:$A$20161,1,FALSE)," ---") -> O60330
A3: Q15413 | B3: 11 | C3: [('QFIFDVVNEGGEQEK', 15578, 'non_standard_modification', True, 'Missed'), ('LLENSSVGLASPSMR', 15585, 'lost_3_aa_Nterm', True, 'Missed'), ('TVQEEEQLKADGK', 15569, 'non_standard_modification', True, 'Missed'), ('QFIFDVVNEGGEQEK', 15579, 'non_standard_modification', True, 'Missed'), ('ISENPALDLPSQGYK', 15564, 'non_standard_modification', True, 'Missed'), ('HGPEVGLGDLSEIIGKDEPPTLESTVQK', 15577, 'non_standard_modification', True, 'Missed'), ('RQFIFDVVNEGGEQEK', 15568, 'non_standard_modification', False, 'Missed'), ('HGPEVGLGDLSEIIGKDEPPTLESTVQK', 15576, 'non_standard_modification', True, 'Missed'), ('QFIFDVVNEGGEQEK', 15580, 'non_standard_modification', True, 'Missed'), ('AEGGEGGEDEIQFLR', 15571, 'regular_tryptic', True, 'Missed'), ('AEGGEGGEDEIQFLR', 15570, 'regular_tryptic', True, 'Missed')] | D3: 6 | E3: 14 | F3: [('ISAAVFHLEQVEQPLR', 15563, nan, True, 'Matched'), ('AEGGEGGEDEIQFLR', 15573, nan, True, 'Matched'), ('LNVYNSVAHFAGIAR', 15586, nan, True, 'Matched'), ('AEVMEPGITTELVHFIK', 15574, nan, True, 'Matched'), ('VEKPEAFTANFFK', 15589, nan, True, 'Matched'), ('AFFENAAEDLEK', 15562, nan, True, 'Matched'), ('ILGDMPDPTQFGIHDDTMEAER', 15584, nan, True, 'Matched'), ('DHPHIEVMR', 15575, nan, True, 'Matched'), ('DLYAFYPMLIR', 15581, nan, True, 'Matched'), ('FLQLLCEGHNSDFQNFLR', 15582, nan, True, 'Matched'), ('QILLLIDPSVFGEHSAGTEEGAEKEEVTQVEEK', 15588, nan, True, 'Matched'), ('GDTDIMSDLFGLHPK', 15565, nan, True, 'Matched'), ('FYTMCGLQEGFEPFAVNMNR', 15583, nan, True, 'Matched'), ('YVDSAQEFIAHLEAIVSSGK', 15590, nan, True, 'Matched')] | G3: 14 | H3: [('QFIFDVVNEGGEQEK', 15578, 'non_standard_modification', True, 'Missed'), ('LLENSSVGLASPSMR', 15585, 'lost_3_aa_Nterm', True, 'Missed'), ('TVQEEEQLKADGK', 15569, 'non_standard_modification', True, 'Missed'), ('QFIFDVVNEGGEQEK', 15579, 'non_standard_modification', True, 'Missed'), ('ISENPALDLPSQGYK', 15564, 'non_standard_modification', True, 'Missed'), ('HGPEVGLGDLSEIIGKDEPPTLESTVQK', 15577, 'non_standard_modification', True, 'Missed'), ('RQFIFDVVNEGGEQEK', 15568, 'non_standard_modification', False, 'Missed'), ('HGPEVGLGDLSEIIGKDEPPTLESTVQK', 15576, 'non_standard_modification', True, 'Missed'), ('QFIFDVVNEGGEQEK', 15580, 'non_standard_modification', True, 'Missed'), ('AEGGEGGEDEIQFLR', 15571, 'regular_tryptic', True, 'Missed'), ('AEGGEGGEDEIQFLR', 15570, 'regular_tryptic', True, 'Missed'), ('ISAAVFHLEQVEQPLR', 15563, nan, True, 'Matched'), ('AEGGEGGEDEIQFLR', 15573, nan, True, 'Matched'), ('LNVYNSVAHFAGIAR', 15586, nan, True, 'Matched'), ('AEVMEPGITTELVHFIK', 15574, nan, True, 'Matched'), ('VEKPEAFTANFFK', 15589, nan, True, 'Matched'), ('AFFENAAEDLEK', 15562, nan, True, 'Matched'), ('ILGDMPDPTQFGIHDDTMEAER', 15584, nan, True, 'Matched'), ('DHPHIEVMR', 15575, nan, True, 'Matched'), ('DLYAFYPMLIR', 15581, nan, True, 'Matched'), ('FLQLLCEGHNSDFQNFLR', 15582, nan, True, 'Matched'), ('QILLLIDPSVFGEHSAGTEEGAEKEEVTQVEEK', 15588, nan, True, 'Matched'), ('GDTDIMSDLFGLHPK', 15565, nan, True, 'Matched'), ('FYTMCGLQEGFEPFAVNMNR', 15583, nan, True, 'Matched'), ('YVDSAQEFIAHLEAIVSSGK', 15590, nan, True, 'Matched')] | I3: 19 | J3: =IFERROR(VLOOKUP(A3,dbg_proteins!$A$2:$A$20161,1,FALSE)," ---") -> Q15413
A4: Q9BYT1 | B4: 30 | C4: [('RSSMPICTV', 21941, 'non_standard_modification', True, 'Missed'), ('RSSMPICTV', 21942, 'non_standard_modification', True, 'Missed'), ('TFNHSGISV', 21622, 'HLA1', True, 'Missed'), ('LSDHLINQGY', 21735, 'IDENTIFIED', True, 'Missed'), ('VYFPALTSL', 21758, 'IDENTIFIED', True, 'Missed'), ('VYFPALTSL', 21739, 'IDENTIFIED', True, 'Missed'), ('LSDHLINQGY', 21721, 'IDENTIFIED', True, 'Missed'), ('LSDHLINQGY', 21737, 'IDENTIFIED', True, 'Missed'), ('KVRESERAF', 21963, 'IDENTIFIED', True, 'Missed'), ('TPLLAHLSSAHLAF', 21966, 'IDENTIFIED', False, 'Missed'), ('VYFPALTSL', 21793, 'IDENTIFIED', True, 'Missed'), ('FPALTSLLSQKVR', 21974, 'lost_3_aa_Nterm', True, 'Missed'), ('TPLLAHLSSAHLA', 21816, 'IDENTIFIED', True, 'Missed'), ('VTPLLAHLSSAHLA', 21898, 'IDENTIFIED', False, 'Missed'), ('YLLSEKDLILA', 21922, 'HLA1', True, 'Missed'), ('LSDHLINQGY', 21700, 'IDENTIFIED', True, 'Missed'), ('YLLSEKDLILA', 21921, 'HLA1', True, 'Missed'), ('VTPLLAHLSSAHLA', 21892, 'IDENTIFIED', False, 'Missed'), ('FRKPAVWAA', 21905, 'IDENTIFIED', True, 'Missed'), ('LSDHLINQGY', 21678, 'IDENTIFIED', True, 'Missed'), ('YLLSEKDLILA', 21924, 'HLA1', True, 'Missed'), ('VTPLLAHLSSAHLAF', 21975, 'HLA2', False, 'Missed'), ('TPLLAHLSSAHLAF', 21968, 'IDENTIFIED', False, 'Missed'), ('YLLSEKDLILA', 21925, 'HLA1', True, 'Missed'), ('KPAVWAAVVSQLSAA', 21947, 'IDENTIFIED', True, 'Missed'), ('YLLSEKDLILA', 21923, 'HLA1', True, 'Missed'), ('YLLSEKDLILA', 21929, 'HLA1', True, 'Missed'), ('YLLSEKDLILA', 21926, 'HLA1', True, 'Missed'), ('YLLSEKDLILA', 21927, 'HLA1', True, 'Missed'), ('YLLSEKDLILA', 21928, 'HLA1', True, 'Missed')] | D4: 10 | E4: 361 | F4: [('TPLLAHLSSAHLA', 21811, nan, True, 'Matched'), ('LSDHLINQGY', 21679, nan, True, 'Matched'), ('TPLLAHLSSAHLA', 21812, nan, True, 'Matched'), ('LSDHLINQGY', 21686, nan, True, 'Matched'), ('LSDHLINQGY', 21684, nan, True, 'Matched'), ('VYFPALTSL', 21770, nan, True, 'Matched'), ('TPLLAHLSSAHLA', 21806, nan, True, 'Matched'), ('LSDHLINQGY', 21706, nan, True, 'Matched'), ('LSDHLINQGY', 21705, nan, True, 'Matched'), ('VDLSSTHEDL', 21951, nan, True, 'Matched'), ('VYFPALTSL', 21771, nan, True, 'Matched'), ('TYSIVGAGSQF', 21933, nan, True, 'Matched'), ('FPALTSLLSQKVRESE', 21838, nan, True, 'Matched'), ('TPLLAHLSSAHLA', 21804, nan, True, 'Matched'), ('VYFPALTSL', 21762, nan, True, 'Matched'), ('FPALTSLLSQKVRESE', 21827, nan, True, 'Matched'), ('TPLLAHLSSAHLA', 21799, nan, True, 'Matched'), ('TPLLAHLSSAHLA', 21805, nan, True, 'Matched'), ('TPLLAHLSSAHLA', 21809, nan, True, 'Matched'), ('MSQDFGWNK', 21953, nan, True, 'Matched'), ('SAHLAFMTF', 21863, nan, True, 'Matched'), ('TYSIVGAGSQF', 21934, nan, True, 'Matched'), ('TYSIVGAGSQF', 21931, nan, True, 'Matched'), ('TYSIVGAGSQF', 21930, nan, True, 'Matched'), ('VYFPALTSL', 21763, nan, True, 'Matched'), ('FPALTSLLSQKVRESE', 21829, nan, True, 'Matched'), ('FPALTSLLSQKVRESE', 21826, nan, True, 'Matched'), ('LSDHLINQGY', 21712, nan, True, 'Matched'), ('LSDHLINQGY', 21711, nan, True, 'Matched'), ('SAHLAFMTF', 21849, nan, True, 'Matched'), ('FPALTSLLSQKVRESE', 21835, nan, True, 'Matched'), ('FPALTSLLSQKVRESE', 21833, nan, True, 'Matched'), ('VYFPALTSL', 21764, nan, True, 'Matched'), ('LSDHLINQGY', 21708, nan, True, 'Matched'), ('LSDHLINQGY', 21707, nan, True, 'Matched'), ('TPLLAHLSSAHLA', 21808, nan, True, 'Matched'), ('FPALTSLLSQKVRESE', 21840, nan, True, 'Matched'), ('VYFPALTSL', 21772, nan, True, 'Matched'), ('TPLLAHLSSAHLA', 21800, nan, True, 'Matched'), ('SAHLAFMTF', 21851, nan, True, 'Matched'), ('NHSGISVNI', 21871, nan, True, 'Matched'), ('TPLLAHLSSAHLA', 21810, nan, True, 'Matched'), ('TYSIVGAGSQF', 21935, nan, True, 'Matched'), ('FPALTSLLSQKVRESE', 21831, nan, True, 'Matched'), ('LSDHLINQGY', 21704, nan, True, 'Matched'), ('LSDHLINQGY', 21703, nan, True, 'Matched'), ('TPLLAHLSSAHLA', 21802, nan, True, 'Matched'), ('LSDHLINQGY', 21691, nan, True, 'Matched'), ('VYFPALTSL', 21761, nan, True, 'Matched'), ('SAHLAFMTF', 21853, nan, True, 'Matched'), ('FPALTSLLSQKVRESE', 21832, nan, True, 'Matched'), ('VYFPALTSL', 21765, nan, True, 'Matched'), ('VYFPALTSL', 21760, nan, True, 'Matched'), ('VYFPALTSL', 21759, nan, True, 'Matched'), ('SAHLAFMTF', 21850, nan, True, 'Matched'), ('FPALTSLLSQKVRESE', 21836, nan, True, 'Matched'), ('SAHLAFMTF', 21852, nan, True, 'Matched'), ('VYFPALTSL', 21766, nan, True, 'Matched'), ('FPALTSLLSQKVRESE', 21848, nan, True, 'Matched'), ('LSDHLINQGY', 21710, nan, True, 'Matched'), ('LSDHLINQGY', 21709, nan, True, 'Matched'), ('NHSGISVNI', 21877, nan, True, 'Matched'), ('NHSGISVNI', 21874, nan, True, 'Matched'), ('NHSGISVNI', 21876, nan, True, 'Matched'), ('NHSGISVNI', 21885, nan, True, 'Matched'), ('TPLLAHLSSAHLA', 21801, nan, True, 'Matched'), ('VYFPALTSL', 21767, nan, True, 'Matched'), ('VYFPALTSL', 21769, nan, True, 'Matched'), ('NHSGISVNI', 21880, nan, True, 'Matched'), ('NHSGISVNI', 21879, nan, True, 'Matched'), ('FPALTSLLSQKVRESE', 21834, nan, True, 'Matched'), ('TYSIVGAGSQF', 21932, nan, True, 'Matched'), ('SAHLAFMTF', 21854, nan, True, 'Matched'), ('VYFPALTSL', 21777, nan, True, 'Matched'), ('NHSGISVNI', 21881, nan, True, 'Matched'), ('NHSGISVNI', 21887, nan, True, 'Matched'), ('VYFPALTSL', 21773, nan, True, 'Matched'), ('FPALTSLLSQKVRESE', 21825, nan, True, 'Matched'), ('MSQDFGWNK', 21955, nan, True, 'Matched'), ('YFPALTSLLSQKVRESE', 21972, nan, False, 'Matched'), ('SAHLAFMTF', 21855, nan, True, 'Matched'), ('NHSGISVNI', 21882, nan, True, 'Matched'), ('MSQDFGWNK', 21956, nan, True, 'Matched'), ('SAHLAFMTF', 21856, nan, True, 'Matched'), ('TFNHSGISV', 21675, nan, True, 'Matched'), ('VYFPALTSL', 21775, nan, True, 'Matched'), ('NHSGISVNI', 21875, nan, True, 'Matched'), ('LSDHLINQGY', 21702, nan, True, 'Matched'), ('LSDHLINQGY', 21701, nan, True, 'Matched'), ('NHSGISVNI', 21886, nan, True, 'Matched'), ('TFNHSGISV', 21586, nan, True, 'Matched'), ('NHSGISVNI', 21888, nan, True, 'Matched'), ('SAHLAFMTF', 21861, nan, True, 'Matched'), ('TFNHSGISV', 21674, nan, True, 'Matched'), ('NHSGISVNI', 21883, nan, True, 'Matched'), ('SAHLAFMTF', 21862, nan, True, 'Matched'), ('SLFSGFLSDHLINQGYR', 21971, nan, False, 'Matched'), ('SAHLAFMTF', 21869, nan, True, 'Matched'), ('LSDHLINQGY', 21713, nan, True, 'Matched'), ('TFNHSGISV', 21595, nan, True, 'Matched'), ('NHSGISVNI', 21872, nan, True, 'Matched'), ('LSDHLINQGY', 21689, nan, True, 'Matched'), ('TFNHSGISV', 21611, nan, True, 'Matched'), ('VYFPALTSL', 21776, nan, True, 'Matched'), ('TPLLAHLSSAHLA', 21813, nan, True, 'Matched'), ('FPALTSLLSQKVRESE', 21846, nan, True, 'Matched'), ('LSDHLINQGY', 21725, nan, True, 'Matched'), ('SAHLAFMTF', 21868, nan, True, 'Matched'), ('SAHLAFMTF', 21866, nan, True, 'Matched'), ('TFNHSGISV', 21663, nan, True, 'Matched'), ('TFNHSGISV', 21642, nan, True, 'Matched'), ('ITAVTPLLAHLSSAH', 21969, nan, True, 'Matched'), ('VYFPALTSL', 21768, nan, True, 'Matched'), ('TFNHSGISV', 21672, nan, True, 'Matched'), ('FPALTSLLSQKVRESE', 21828, nan, True, 'Matched'), ('FPALTSLLSQKVRESE', 21841, nan, True, 'Matched'), ('TFNHSGISV', 21592, nan, True, 'Matched'), ('TFNHSGISV', 21598, nan, True, 'Matched'), ('TFNHSGISV', 21645, nan, True, 'Matched'), ('NHSGISVNI', 21873, nan, True, 'Matched'), ('TFNHSGISV', 21603, nan, True, 'Matched'), ('YFPALTSLLSQKVRESE', 21973, nan, False, 'Matched'), ('SAHLAFMTF', 21858, nan, True, 'Matched'), ('TFNHSGISV', 21617, nan, True, 'Matched'), ('SAHLAFMTF', 21859, nan, True, 'Matched'), ('TFNHSGISV', 21606, nan, True, 'Matched'), ('TYSIVGAGSQF', 21936, nan, True, 'Matched'), ('LSDHLINQGY', 21688, nan, True, 'Matched'), ('LSDHLINQGY', 21738, nan, True, 'Matched'), ('TFNHSGISV', 21671, nan, True, 'Matched'), ('TFNHSGISV', 21659, nan, True, 'Matched'), ('TFNHSGISV', 21585, nan, True, 'Matched'), ('TFNHSGISV', 21667, nan, True, 'Matched'), ('TFNHSGISV', 21643, nan, True, 'Matched'), ('TPLLAHLSSAHLA', 21807, nan, True, 'Matched'), ('TFNHSGISV', 21621, nan, True, 'Matched'), ('TFNHSGISV', 21616, nan, True, 'Matched'), ('TFNHSGISV', 21624, nan, True, 'Matched'), ('LSDHLINQGY', 21685, nan, True, 'Matched'), ('TFNHSGISV', 21591, nan, True, 'Matched'), ('TFNHSGISV', 21656, nan, True, 'Matched'), ('TPLLAHLSSAHLA', 21803, nan, True, 'Matched'), ('TFNHSGISV', 21618, nan, True, 'Matched'), ('HLSSAHLAF', 21912, nan, True, 'Matched'), ('TFNHSGISV', 21669, nan, True, 'Matched'), ('TFNHSGISV', 21590, nan, True, 'Matched'), ('TFNHSGISV', 21604, nan, True, 'Matched'), ('TFNHSGISV', 21650, nan, True, 'Matched'), ('TFNHSGISV', 21589, nan, True, 'Matched'), ('TFNHSGISV', 21649, nan, True, 'Matched'), ('TFNHSGISV', 21605, nan, True, 'Matched'), ('TFNHSGISV', 21583, nan, True, 'Matched'), ('TFNHSGISV', 21600, nan, True, 'Matched'), ('NHSGISVNI', 21884, nan, True, 'Matched'), ('TFNHSGISV', 21596, nan, True, 'Matched'), ('TFNHSGISV', 21638, nan, True, 'Matched'), ('TFNHSGISV', 21612, nan, True, 'Matched'), ('ITAVTPLLAHLSSAH', 21970, nan, True, 'Matched'), ('TFNHSGISV', 21601, nan, True, 'Matched'), ('TFNHSGISV', 21593, nan, True, 'Matched'), ('TFNHSGISV', 21660, nan, True, 'Matched'), ('FPDAKGWIF', 21960, nan, True, 'Matched'), ('TFNHSGISV', 21628, nan, True, 'Matched'), ('TFNHSGISV', 21608, nan, True, 'Matched'), ('TFNHSGISV', 21673, nan, True, 'Matched'), ('TFNHSGISV', 21602, nan, True, 'Matched'), ('TFNHSGISV', 21623, nan, True, 'Matched'), ('TFNHSGISV', 21633, nan, True, 'Matched'), ('TFNHSGISV', 21635, nan, True, 'Matched'), ('NHSGISVNI', 21889, nan, True, 'Matched'), ('TFNHSGISV', 21629, nan, True, 'Matched'), ('TFNHSGISV', 21614, nan, True, 'Matched'), ('SAHLAFMTF', 21864, nan, True, 'Matched'), ('HLSSAHLAF', 21918, nan, True, 'Matched'), ('TFNHSGISV', 21652, nan, True, 'Matched'), ('TFNHSGISV', 21607, nan, True, 'Matched'), ('TFNHSGISV', 21626, nan, True, 'Matched'), ('TFNHSGISV', 21655, nan, True, 'Matched'), ('TFNHSGISV', 21637, nan, True, 'Matched'), ('TFNHSGISV', 21619, nan, True, 'Matched'), ('TFNHSGISV', 21588, nan, True, 'Matched'), ('LSDHLINQGY', 21714, nan, True, 'Matched'), ('TPLLAHLSSAHLA', 21818, nan, True, 'Matched'), ('TFNHSGISV', 21658, nan, True, 'Matched'), ('TFNHSGISV', 21631, nan, True, 'Matched'), ('HLSSAHLAF', 21919, nan, True, 'Matched'), ('TFNHSGISV', 21653, nan, True, 'Matched'), ('TFNHSGISV', 21640, nan, True, 'Matched'), ('HLSSAHLAF', 21920, nan, True, 'Matched'), ('TFNHSGISV', 21647, nan, True, 'Matched'), ('TFNHSGISV', 21634, nan, True, 'Matched'), ('VYFPALTSL', 21774, nan, True, 'Matched'), ('TFNHSGISV', 21582, nan, True, 'Matched'), ('LSDHLINQGY', 21726, nan, True, 'Matched'), ('TFNHSGISV', 21627, nan, True, 'Matched'), ('SAHLAFMTF', 21857, nan, True, 'Matched'), ('TFNHSGISV', 21632, nan, True, 'Matched'), ('FPALTSLLSQKVRESE', 21847, nan, True, 'Matched'), ('TFNHSGISV', 21662, nan, True, 'Matched'), ('HLSSAHLAF', 21917, nan, True, 'Matched'), ('TFNHSGISV', 21597, nan, True, 'Matched'), ('HLSSAHLAF', 21914, nan, True, 'Matched'), ('TFNHSGISV', 21630, nan, True, 'Matched'), ('HLSSAHLAF', 21916, nan, True, 'Matched'), ('TFNHSGISV', 21609, nan, True, 'Matched'), ('TFNHSGISV', 21654, nan, True, 'Matched'), ('TFNHSGISV', 21594, nan, True, 'Matched'), ('TFNHSGISV', 21615, nan, True, 'Matched'), ('TFNHSGISV', 21664, nan, True, 'Matched'), ('TFNHSGISV', 21584, nan, True, 'Matched'), ('TFNHSGISV', 21599, nan, True, 'Matched'), ('LSDHLINQGY', 21728, nan, True, 'Matched'), ('TPLLAHLSSAHLA', 21820, nan, True, 'Matched'), ('FPDAKGWIF', 21961, nan, True, 'Matched'), ('TFNHSGISV', 21651, nan, True, 'Matched'), ('LSDHLINQGY', 21681, nan, True, 'Matched'), ('FPALTSLLSQKVRESE', 21839, nan, True, 'Matched'), ('TFNHSGISV', 21620, nan, True, 'Matched'), ('TFNHSGISV', 21610, nan, True, 'Matched'), ('TFNHSGISV', 21587, nan, True, 'Matched'), ('TFNHSGISV', 21670, nan, True, 'Matched'), ('SAHLAFMTF', 21870, nan, True, 'Matched'), ('HLSSAHLAF', 21913, nan, True, 'Matched'), ('TFNHSGISV', 21613, nan, True, 'Matched'), ('TPLLAHLSSAHLA', 21821, nan, True, 'Matched'), ('NHSGISVNI', 21878, nan, True, 'Matched'), ('FPALTSLLSQKVRESE', 21843, nan, True, 'Matched'), ('TFNHSGISV', 21636, nan, True, 'Matched'), ('LSDHLINQGY', 21694, nan, True, 'Matched'), ('LSDHLINQGY', 21693, nan, True, 'Matched'), ('LSDHLINQGY', 21729, nan, True, 'Matched'), ('LSDHLINQGY', 21718, nan, True, 'Matched'), ('LSDHLINQGY', 21683, nan, True, 'Matched'), ('LSDHLINQGY', 21722, nan, True, 'Matched'), ('LSDHLINQGY', 21724, nan, True, 'Matched'), ('FPALTSLLSQKVRESE', 21837, nan, True, 'Matched'), ('LSDHLINQGY', 21687, nan, True, 'Matched'), ('LSDHLINQGY', 21720, nan, True, 'Matched'), ('HLSSAHLAF', 21915, nan, True, 'Matched'), ('LSDHLINQGY', 21692, nan, True, 'Matched'), ('TFNHSGISV', 21661, nan, True, 'Matched'), ('LSDHLINQGY', 21723, nan, True, 'Matched'), ('TFNHSGISV', 21668, nan, True, 'Matched'), ('VDLSSTHEDL', 21949, nan, True, 'Matched'), ('TFNHSGISV', 21644, nan, True, 'Matched'), ('FPDAKGWIF', 21962, nan, True, 'Matched'), ('TFNHSGISV', 21639, nan, True, 'Matched'), ('LSDHLINQGY', 21696, nan, True, 'Matched'), ('LSDHLINQGY', 21695, nan, True, 'Matched'), ('VDLSSTHEDL', 21948, nan, True, 'Matched'), ('TFNHSGISV', 21666, nan, True, 'Matched'), ('TFNHSGISV', 21665, nan, True, 'Matched'), ('LSDHLINQGY', 21719, nan, True, 'Matched'), ('VTPLLAHLSSAHLA', 21899, nan, False, 'Matched'), ('SAHLAFMTF', 21865, nan, True, 'Matched'), ('TFNHSGISV', 21641, nan, True, 'Matched'), ('VTPLLAHLSSAHLA', 21895, nan, False, 'Matched'), ('TFNHSGISV', 21648, nan, True, 'Matched'), ('ETFPDAKGWIF', 21958, nan, False, 'Matched'), ('TPLLAHLSSAHLA', 21822, nan, True, 'Matched'), ('LSDHLINQGY', 21682, nan, True, 'Matched'), ('SAHLAFMTF', 21860, nan, True, 'Matched'), ('FPALTSLLSQKVRESE', 21842, nan, True, 'Matched'), ('LSDHLINQGY', 21730, nan, True, 'Matched'), ('LSDHLINQGY', 21717, nan, True, 'Matched'), ('VYFPALTSL', 21755, nan, True, 'Matched'), ('FPALTSLLSQKVRESE', 21844, nan, True, 'Matched'), ('TFNHSGISV', 21646, nan, True, 'Matched'), ('RSSMPICTV', 21940, nan, True, 'Matched'), ('TPLLAHLSSAHLA', 21823, nan, True, 'Matched'), ('ETFPDAKGWIF', 21959, nan, False, 'Matched'), ('LSDHLINQGY', 21732, nan, True, 'Matched'), ('RSSMPICTV', 21938, nan, True, 'Matched'), ('LSDHLINQGY', 21733, nan, True, 'Matched'), ('TFNHSGISV', 21657, nan, True, 'Matched'), ('VYFPALTSL', 21742, nan, True, 'Matched'), ('LSDHLINQGY', 21716, nan, True, 'Matched'), ('ETFPDAKGWIF', 21957, nan, False, 'Matched'), ('VTPLLAHLSSAHLA', 21896, nan, False, 'Matched'), ('TPLLAHLSSAHLA', 21814, nan, True, 'Matched'), ('VYFPALTSL', 21741, nan, True, 'Matched'), ('SAHLAFMTF', 21867, nan, True, 'Matched'), ('LSDHLINQGY', 21677, nan, True, 'Matched'), ('TPLLAHLSSAHLA', 21815, nan, True, 'Matched'), ('LSDHLINQGY', 21715, nan, True, 'Matched'), ('FPALTSLLSQKVRESE', 21845, nan, True, 'Matched'), ('LSDHLINQGY', 21734, nan, True, 'Matched'), ('LSDHLINQGY', 21680, nan, True, 'Matched'), ('VYFPALTSL', 21751, nan, True, 'Matched'), ('VYFPALTSL', 21780, nan, True, 'Matched'), ('RSSMPICTV', 21939, nan, True, 'Matched'), ('LSDHLINQGY', 21727, nan, True, 'Matched'), ('VYFPALTSL', 21740, nan, True, 'Matched'), ('VYFPALTSL', 21786, nan, True, 'Matched'), ('LSDHLINQGY', 21697, nan, True, 'Matched'), ('VYFPALTSL', 21798, nan, True, 'Matched'), ('VYFPALTSL', 21797, nan, True, 'Matched'), ('LSDHLINQGY', 21699, nan, True, 'Matched'), ('LSDHLINQGY', 21698, nan, True, 'Matched'), ('LSDHLINQGY', 21690, nan, True, 'Matched'), ('VYFPALTSL', 21790, nan, True, 'Matched'), ('VTPLLAHLSSAHLA', 21890, nan, False, 'Matched'), ('VDLSSTHEDL', 21952, nan, True, 'Matched'), ('LSDHLINQGY', 21736, nan, True, 'Matched'), ('VYFPALTSL', 21746, nan, True, 'Matched'), ('VYFPALTSL', 21782, nan, True, 'Matched'), ('VYFPALTSL', 21788, nan, True, 'Matched'), ('VYFPALTSL', 21783, nan, True, 'Matched'), ('VYFPALTSL', 21743, nan, True, 'Matched'), ('VYFPALTSL', 21749, nan, True, 'Matched'), ('TFNHSGISV', 21625, nan, True, 'Matched'), ('VTPLLAHLSSAHLA', 21894, nan, False, 'Matched'), ('VYFPALTSL', 21781, nan, True, 'Matched'), ('VYFPALTSL', 21753, nan, True, 'Matched'), ('VYFPALTSL', 21784, nan, True, 'Matched'), ('LSDHLINQGY', 21731, nan, True, 'Matched'), ('VYFPALTSL', 21748, nan, True, 'Matched'), ('VYFPALTSL', 21787, nan, True, 'Matched'), ('VYFPALTSL', 21791, nan, True, 'Matched'), ('VYFPALTSL', 21747, nan, True, 'Matched'), ('VYFPALTSL', 21792, nan, True, 'Matched'), ('VYFPALTSL', 21789, nan, True, 'Matched'), ('VYFPALTSL', 21778, nan, True, 'Matched'), ('VYFPALTSL', 21757, nan, True, 'Matched'), ('VYFPALTSL', 21779, nan, True, 'Matched'), ('VYFPALTSL', 21794, nan, True, 'Matched'), ('TPLLAHLSSAHLA', 21819, nan, True, 'Matched'), ('VYFPALTSL', 21750, nan, True, 'Matched'), ('VYFPALTSL', 21795, nan, True, 'Matched'), ('VYFPALTSL', 21745, nan, True, 'Matched'), ('KVRESERAF', 21964, nan, True, 'Matched'), ('VYFPALTSL', 21752, nan, True, 'Matched'), ('VYFPALTSL', 21785, nan, True, 'Matched'), ('FPALTSLLSQKVRESE', 21830, nan, True, 'Matched'), ('KVRESERAF', 21965, nan, True, 'Matched'), ('TPLLAHLSSAHLA', 21817, nan, True, 'Matched'), ('VYFPALTSL', 21754, nan, True, 'Matched'), ('LSDHLINQGY', 21676, nan, True, 'Matched'), ('RSSMPICTV', 21937, nan, True, 'Matched'), ('VYFPALTSL', 21796, nan, True, 'Matched'), ('VYFPALTSL', 21756, nan, True, 'Matched'), ('VTPLLAHLSSAHLA', 21893, nan, False, 'Matched'), ('FRKPAVWAA', 21906, nan, True, 'Matched'), ('VYFPALTSL', 21744, nan, True, 'Matched'), ('TPLLAHLSSAHLA', 21824, nan, True, 'Matched'), ('KPAVWAAVVSQLSAA', 21946, nan, True, 'Matched'), ('KPAVWAAVVSQLSAA', 21944, nan, True, 'Matched'), ('KPAVWAAVVSQLSAA', 21945, nan, True, 'Matched'), ('KPAVWAAVVSQLSAA', 21943, nan, True, 'Matched'), ('VTPLLAHLSSAHLA', 21900, nan, False, 'Matched'), ('VTPLLAHLSSAHLA', 21891, nan, False, 'Matched'), ('FRKPAVWAA', 21904, nan, True, 'Matched'), ('FRKPAVWAA', 21908, nan, True, 'Matched'), ('VTPLLAHLSSAHLA', 21897, nan, False, 'Matched'), ('FRKPAVWAA', 21909, nan, True, 'Matched'), ('FRKPAVWAA', 21902, nan, True, 'Matched'), ('FRKPAVWAA', 21901, nan, True, 'Matched'), ('FRKPAVWAA', 21907, nan, True, 'Matched'), ('TPLLAHLSSAHLAF', 21967, nan, False, 'Matched'), ('FRKPAVWAA', 21903, nan, True, 'Matched'), ('FRKPAVWAA', 21910, nan, True, 'Matched')] | G4: 17 | H4: [('RSSMPICTV', 21941, 'non_standard_modification', True, 'Missed'), ('RSSMPICTV', 21942, 'non_standard_modification', True, 'Missed'), ('TFNHSGISV', 21622, 'HLA1', True, 'Missed'), ('LSDHLINQGY', 21735, 'IDENTIFIED', True, 'Missed'), ('VYFPALTSL', 21758, 'IDENTIFIED', True, 'Missed'), ('VYFPALTSL', 21739, 'IDENTIFIED', True, 'Missed'), ('LSDHLINQGY', 21721, 'IDENTIFIED', True, 'Missed'), ('LSDHLINQGY', 21737, 'IDENTIFIED', True, 'Missed'), ('KVRESERAF', 21963, 'IDENTIFIED', True, 'Missed'), ('TPLLAHLSSAHLAF', 21966, 'IDENTIFIED', False, 'Missed'), ('VYFPALTSL', 21793, 'IDENTIFIED', True, 'Missed'), ('FPALTSLLSQKVR', 21974, 'lost_3_aa_Nterm', True, 'Missed'), ('TPLLAHLSSAHLA', 21816, 'IDENTIFIED', True, 'Missed'), ('VTPLLAHLSSAHLA', 21898, 'IDENTIFIED', False, 'Missed'), ('YLLSEKDLILA', 21922, 'HLA1', True, 'Missed'), ('LSDHLINQGY', 21700, 'IDENTIFIED', True, 'Missed'), ('YLLSEKDLILA', 21921, 'HLA1', True, 'Missed'), ('VTPLLAHLSSAHLA', 21892, 'IDENTIFIED', False, 'Missed'), ('FRKPAVWAA', 21905, 'IDENTIFIED', True, 'Missed'), ('LSDHLINQGY', 21678, 'IDENTIFIED', True, 'Missed'), ('YLLSEKDLILA', 21924, 'HLA1', True, 'Missed'), ('VTPLLAHLSSAHLAF', 21975, 'HLA2', False, 'Missed'), ('TPLLAHLSSAHLAF', 21968, 'IDENTIFIED', False, 'Missed'), ('YLLSEKDLILA', 21925, 'HLA1', True, 'Missed'), ('KPAVWAAVVSQLSAA', 21947, 'IDENTIFIED', True, 'Missed'), ('YLLSEKDLILA', 21923, 'HLA1', True, 'Missed'), ('YLLSEKDLILA', 21929, 'HLA1', True, 'Missed'), ('YLLSEKDLILA', 21926, 'HLA1', True, 'Missed'), ('YLLSEKDLILA', 21927, 'HLA1', True, 'Missed'), ('YLLSEKDLILA', 21928, 'HLA1', True, 'Missed'), ('TPLLAHLSSAHLA', 21811, nan, True, 'Matched'), ('LSDHLINQGY', 21679, nan, True, 'Matched'), ('TPLLAHLSSAHLA', 21812, nan, True, 'Matched'), ('LSDHLINQGY', 21686, nan, True, 'Matched'), ('LSDHLINQGY', 21684, nan, True, 'Matched'), ('VYFPALTSL', 21770, nan, True, 'Matched'), ('TPLLAHLSSAHLA', 21806, nan, True, 'Matched'), ('LSDHLINQGY', 21706, nan, True, 'Matched'), ('LSDHLINQGY', 21705, nan, True, 'Matched'), ('VDLSSTHEDL', 21951, nan, True, 'Matched'), ('VYFPALTSL', 21771, nan, True, 'Matched'), ('TYSIVGAGSQF', 21933, nan, True, 'Matched'), ('FPALTSLLSQKVRESE', 21838, nan, False, 'Matched'), ('TPLLAHLSSAHLA', 21804, nan, True, 'Matched'), ('VYFPALTSL', 21762, nan, True, 'Matched'), ('FPALTSLLSQKVRESE', 21827, nan, False, 'Matched'), ('TPLLAHLSSAHLA', 21799, nan, True, 'Matched'), ('TPLLAHLSSAHLA', 21805, nan, True, 'Matched'), ('TPLLAHLSSAHLA', 21809, nan, True, 'Matched'), ('MSQDFGWNK', 21953, nan, True, 'Matched'), ('SAHLAFMTF', 21863, nan, True, 'Matched'), ('TYSIVGAGSQF', 21934, nan, True, 'Matched'), ('TYSIVGAGSQF', 21931, nan, True, 'Matched'), ('TYSIVGAGSQF', 21930, nan, True, 'Matched'), ('VYFPALTSL', 21763, nan, True, 'Matched'), ('FPALTSLLSQKVRESE', 21829, nan, False, 'Matched'), ('FPALTSLLSQKVRESE', 21826, nan, False, 'Matched'), ('LSDHLINQGY', 21712, nan, True, 'Matched'), ('LSDHLINQGY', 21711, nan, True, 'Matched'), ('SAHLAFMTF', 21849, nan, True, 'Matched'), ('FPALTSLLSQKVRESE', 21835, nan, False, 'Matched'), ('FPALTSLLSQKVRESE', 21833, nan, False, 'Matched'), ('VYFPALTSL', 21764, nan, True, 'Matched'), ('LSDHLINQGY', 21708, nan, True, 'Matched'), ('LSDHLINQGY', 21707, nan, True, 'Matched'), ('TPLLAHLSSAHLA', 21808, nan, True, 'Matched'), ('FPALTSLLSQKVRESE', 21840, nan, False, 'Matched'), ('VYFPALTSL', 21772, nan, True, 'Matched'), ('TPLLAHLSSAHLA', 21800, nan, True, 'Matched'), ('SAHLAFMTF', 21851, nan, True, 'Matched'), ('NHSGISVNI', 21871, nan, True, 'Matched'), ('TPLLAHLSSAHLA', 21810, nan, True, 'Matched'), ('TYSIVGAGSQF', 21935, nan, True, 'Matched'), ('FPALTSLLSQKVRESE', 21831, nan, False, 'Matched'), ('LSDHLINQGY', 21704, nan, True, 'Matched'), ('LSDHLINQGY', 21703, nan, True, 'Matched'), ('TPLLAHLSSAHLA', 21802, nan, True, 'Matched'), ('LSDHLINQGY', 21691, nan, True, 'Matched'), ('VYFPALTSL', 21761, nan, True, 'Matched'), ('SAHLAFMTF', 21853, nan, True, 'Matched'), ('FPALTSLLSQKVRESE', 21832, nan, False, 'Matched'), ('VYFPALTSL', 21765, nan, True, 'Matched'), ('VYFPALTSL', 21760, nan, True, 'Matched'), ('VYFPALTSL', 21759, nan, True, 'Matched'), ('SAHLAFMTF', 21850, nan, True, 'Matched'), ('FPALTSLLSQKVRESE', 21836, nan, False, 'Matched'), ('SAHLAFMTF', 21852, nan, True, 'Matched'), ('VYFPALTSL', 21766, nan, True, 'Matched'), ('FPALTSLLSQKVRESE', 21848, nan, False, 'Matched'), ('LSDHLINQGY', 21710, nan, True, 'Matched'), ('LSDHLINQGY', 21709, nan, True, 'Matched'), ('NHSGISVNI', 21877, nan, True, 'Matched'), ('NHSGISVNI', 21874, nan, True, 'Matched'), ('NHSGISVNI', 21876, nan, True, 'Matched'), ('NHSGISVNI', 21885, nan, True, 'Matched'), ('TPLLAHLSSAHLA', 21801, nan, True, 'Matched'), ('VYFPALTSL', 21767, nan, True, 'Matched'), ('VYFPALTSL', 21769, nan, True, 'Matched'), ('NHSGISVNI', 21880, nan, True, 'Matched'), ('NHSGISVNI', 21879, nan, True, 'Matched'), ('FPALTSLLSQKVRESE', 21834, nan, False, 'Matched'), ('TYSIVGAGSQF', 21932, nan, True, 'Matched'), ('SAHLAFMTF', 21854, nan, True, 'Matched'), ('VYFPALTSL', 21777, nan, True, 'Matched'), ('NHSGISVNI', 21881, nan, True, 'Matched'), ('NHSGISVNI', 21887, nan, True, 'Matched'), ('VYFPALTSL', 21773, nan, True, 'Matched'), ('FPALTSLLSQKVRESE', 21825, nan, False, 'Matched'), ('MSQDFGWNK', 21955, nan, True, 'Matched'), ('YFPALTSLLSQKVRESE', 21972, nan, False, 'Matched'), ('SAHLAFMTF', 21855, nan, True, 'Matched'), ('NHSGISVNI', 21882, nan, True, 'Matched'), ('MSQDFGWNK', 21956, nan, True, 'Matched'), ('SAHLAFMTF', 21856, nan, True, 'Matched'), ('TFNHSGISV', 21675, nan, True, 'Matched'), ('VYFPALTSL', 21775, nan, True, 'Matched'), ('NHSGISVNI', 21875, nan, True, 'Matched'), ('LSDHLINQGY', 21702, nan, True, 'Matched'), ('LSDHLINQGY', 21701, nan, True, 'Matched'), ('NHSGISVNI', 21886, nan, True, 'Matched'), ('TFNHSGISV', 21586, nan, True, 'Matched'), ('NHSGISVNI', 21888, nan, True, 'Matched'), ('SAHLAFMTF', 21861, nan, True, 'Matched'), ('TFNHSGISV', 21674, nan, True, 'Matched'), ('NHSGISVNI', 21883, nan, True, 'Matched'), ('SAHLAFMTF', 21862, nan, True, 'Matched'), ('SLFSGFLSDHLINQGYR', 21971, nan, False, 'Matched'), ('SAHLAFMTF', 21869, nan, True, 'Matched'), ('LSDHLINQGY', 21713, nan, True, 'Matched'), ('TFNHSGISV', 21595, nan, True, 'Matched'), ('NHSGISVNI', 21872, nan, True, 'Matched'), ('LSDHLINQGY', 21689, nan, True, 'Matched'), ('TFNHSGISV', 21611, nan, True, 'Matched'), ('VYFPALTSL', 21776, nan, True, 'Matched'), ('TPLLAHLSSAHLA', 21813, nan, True, 'Matched'), ('FPALTSLLSQKVRESE', 21846, nan, False, 'Matched'), ('LSDHLINQGY', 21725, nan, True, 'Matched'), ('SAHLAFMTF', 21868, nan, True, 'Matched'), ('SAHLAFMTF', 21866, nan, True, 'Matched'), ('TFNHSGISV', 21663, nan, True, 'Matched'), ('TFNHSGISV', 21642, nan, True, 'Matched'), ('ITAVTPLLAHLSSAH', 21969, nan, True, 'Matched'), ('VYFPALTSL', 21768, nan, True, 'Matched'), ('TFNHSGISV', 21672, nan, True, 'Matched'), ('FPALTSLLSQKVRESE', 21828, nan, False, 'Matched'), ('FPALTSLLSQKVRESE', 21841, nan, False, 'Matched'), ('TFNHSGISV', 21592, nan, True, 'Matched'), ('TFNHSGISV', 21598, nan, True, 'Matched'), ('TFNHSGISV', 21645, nan, True, 'Matched'), ('NHSGISVNI', 21873, nan, True, 'Matched'), ('TFNHSGISV', 21603, nan, True, 'Matched'), ('YFPALTSLLSQKVRESE', 21973, nan, False, 'Matched'), ('SAHLAFMTF', 21858, nan, True, 'Matched'), ('TFNHSGISV', 21617, nan, True, 'Matched'), ('SAHLAFMTF', 21859, nan, True, 'Matched'), ('TFNHSGISV', 21606, nan, True, 'Matched'), ('TYSIVGAGSQF', 21936, nan, True, 'Matched'), ('LSDHLINQGY', 21688, nan, True, 'Matched'), ('LSDHLINQGY', 21738, nan, True, 'Matched'), ('TFNHSGISV', 21671, nan, True, 'Matched'), ('TFNHSGISV', 21659, nan, True, 'Matched'), ('TFNHSGISV', 21585, nan, True, 'Matched'), ('TFNHSGISV', 21667, nan, True, 'Matched'), ('TFNHSGISV', 21643, nan, True, 'Matched'), ('TPLLAHLSSAHLA', 21807, nan, True, 'Matched'), ('TFNHSGISV', 21621, nan, True, 'Matched'), ('TFNHSGISV', 21616, nan, True, 'Matched'), ('TFNHSGISV', 21624, nan, True, 'Matched'), ('LSDHLINQGY', 21685, nan, True, 'Matched'), ('TFNHSGISV', 21591, nan, True, 'Matched'), ('TFNHSGISV', 21656, nan, True, 'Matched'), ('TPLLAHLSSAHLA', 21803, nan, True, 'Matched'), ('TFNHSGISV', 21618, nan, True, 'Matched'), ('HLSSAHLAF', 21912, nan, True, 'Matched'), ('TFNHSGISV', 21669, nan, True, 'Matched'), ('TFNHSGISV', 21590, nan, True, 'Matched'), ('TFNHSGISV', 21604, nan, True, 'Matched'), ('TFNHSGISV', 21650, nan, True, 'Matched'), ('TFNHSGISV', 21589, nan, True, 'Matched'), ('TFNHSGISV', 21649, nan, True, 'Matched'), ('TFNHSGISV', 21605, nan, True, 'Matched'), ('TFNHSGISV', 21583, nan, True, 'Matched'), ('TFNHSGISV', 21600, nan, True, 'Matched'), ('NHSGISVNI', 21884, nan, True, 'Matched'), ('TFNHSGISV', 21596, nan, True, 'Matched'), ('TFNHSGISV', 21638, nan, True, 'Matched'), ('TFNHSGISV', 21612, nan, True, 'Matched'), ('ITAVTPLLAHLSSAH', 21970, nan, True, 'Matched'), ('TFNHSGISV', 21601, nan, True, 'Matched'), ('TFNHSGISV', 21593, nan, True, 'Matched'), ('TFNHSGISV', 21660, nan, True, 'Matched'), ('FPDAKGWIF', 21960, nan, True, 'Matched'), ('TFNHSGISV', 21628, nan, True, 'Matched'), ('TFNHSGISV', 21608, nan, True, 'Matched'), ('TFNHSGISV', 21673, nan, True, 'Matched'), ('TFNHSGISV', 21602, nan, True, 'Matched'), ('TFNHSGISV', 21623, nan, True, 'Matched'), ('TFNHSGISV', 21633, nan, True, 'Matched'), ('TFNHSGISV', 21635, nan, True, 'Matched'), ('NHSGISVNI', 21889, nan, True, 'Matched'), ('TFNHSGISV', 21629, nan, True, 'Matched'), ('TFNHSGISV', 21614, nan, True, 'Matched'), ('SAHLAFMTF', 21864, nan, True, 'Matched'), ('HLSSAHLAF', 21918, nan, True, 'Matched'), ('TFNHSGISV', 21652, nan, True, 'Matched'), ('TFNHSGISV', 21607, nan, True, 'Matched'), ('TFNHSGISV', 21626, nan, True, 'Matched'), ('TFNHSGISV', 21655, nan, True, 'Matched'), ('TFNHSGISV', 21637, nan, True, 'Matched'), ('TFNHSGISV', 21619, nan, True, 'Matched'), ('TFNHSGISV', 21588, nan, True, 'Matched'), ('LSDHLINQGY', 21714, nan, True, 'Matched'), ('TPLLAHLSSAHLA', 21818, nan, True, 'Matched'), ('TFNHSGISV', 21658, nan, True, 'Matched'), ('TFNHSGISV', 21631, nan, True, 'Matched'), ('HLSSAHLAF', 21919, nan, True, 'Matched'), ('TFNHSGISV', 21653, nan, True, 'Matched'), ('TFNHSGISV', 21640, nan, True, 'Matched'), ('HLSSAHLAF', 21920, nan, True, 'Matched'), ('TFNHSGISV', 21647, nan, True, 'Matched'), ('TFNHSGISV', 21634, nan, True, 'Matched'), ('VYFPALTSL', 21774, nan, True, 'Matched'), ('TFNHSGISV', 21582, nan, True, 'Matched'), ('LSDHLINQGY', 21726, nan, True, 'Matched'), ('TFNHSGISV', 21627, nan, True, 'Matched'), ('SAHLAFMTF', 21857, nan, True, 'Matched'), ('TFNHSGISV', 21632, nan, True, 'Matched'), ('FPALTSLLSQKVRESE', 21847, nan, False, 'Matched'), ('TFNHSGISV', 21662, nan, True, 'Matched'), ('HLSSAHLAF', 21917, nan, True, 'Matched'), ('TFNHSGISV', 21597, nan, True, 'Matched'), ('HLSSAHLAF', 21914, nan, True, 'Matched'), ('TFNHSGISV', 21630, nan, True, 'Matched'), ('HLSSAHLAF', 21916, nan, True, 'Matched'), ('TFNHSGISV', 21609, nan, True, 'Matched'), ('TFNHSGISV', 21654, nan, True, 'Matched'), ('TFNHSGISV', 21594, nan, True, 'Matched'), ('TFNHSGISV', 21615, nan, True, 'Matched'), ('TFNHSGISV', 21664, nan, True, 'Matched'), ('TFNHSGISV', 21584, nan, True, 'Matched'), ('TFNHSGISV', 21599, nan, True, 'Matched'), ('LSDHLINQGY', 21728, nan, True, 'Matched'), ('TPLLAHLSSAHLA', 21820, nan, True, 'Matched'), ('FPDAKGWIF', 21961, nan, True, 'Matched'), ('TFNHSGISV', 21651, nan, True, 'Matched'), ('LSDHLINQGY', 21681, nan, True, 'Matched'), ('FPALTSLLSQKVRESE', 21839, nan, False, 'Matched'), ('TFNHSGISV', 21620, nan, True, 'Matched'), ('TFNHSGISV', 21610, nan, True, 'Matched'), ('TFNHSGISV', 21587, nan, True, 'Matched'), ('TFNHSGISV', 21670, nan, True, 'Matched'), ('SAHLAFMTF', 21870, nan, True, 'Matched'), ('HLSSAHLAF', 21913, nan, True, 'Matched'), ('TFNHSGISV', 21613, nan, True, 'Matched'), ('TPLLAHLSSAHLA', 21821, nan, True, 'Matched'), ('NHSGISVNI', 21878, nan, True, 'Matched'), ('FPALTSLLSQKVRESE', 21843, nan, False, 'Matched'), ('TFNHSGISV', 21636, nan, True, 'Matched'), ('LSDHLINQGY', 21694, nan, True, 'Matched'), ('LSDHLINQGY', 21693, nan, True, 'Matched'), ('LSDHLINQGY', 21729, nan, True, 'Matched'), ('LSDHLINQGY', 21718, nan, True, 'Matched'), ('LSDHLINQGY', 21683, nan, True, 'Matched'), ('LSDHLINQGY', 21722, nan, True, 'Matched'), ('LSDHLINQGY', 21724, nan, True, 'Matched'), ('FPALTSLLSQKVRESE', 21837, nan, False, 'Matched'), ('LSDHLINQGY', 21687, nan, True, 'Matched'), ('LSDHLINQGY', 21720, nan, True, 'Matched'), ('HLSSAHLAF', 21915, nan, True, 'Matched'), ('LSDHLINQGY', 21692, nan, True, 'Matched'), ('TFNHSGISV', 21661, nan, True, 'Matched'), ('LSDHLINQGY', 21723, nan, True, 'Matched'), ('TFNHSGISV', 21668, nan, True, 'Matched'), ('VDLSSTHEDL', 21949, nan, True, 'Matched'), ('TFNHSGISV', 21644, nan, True, 'Matched'), ('FPDAKGWIF', 21962, nan, True, 'Matched'), ('TFNHSGISV', 21639, nan, True, 'Matched'), ('LSDHLINQGY', 21696, nan, True, 'Matched'), ('LSDHLINQGY', 21695, nan, True, 'Matched'), ('VDLSSTHEDL', 21948, nan, True, 'Matched'), ('TFNHSGISV', 21666, nan, True, 'Matched'), ('TFNHSGISV', 21665, nan, True, 'Matched'), ('LSDHLINQGY', 21719, nan, True, 'Matched'), ('VTPLLAHLSSAHLA', 21899, nan, False, 'Matched'), ('SAHLAFMTF', 21865, nan, True, 'Matched'), ('TFNHSGISV', 21641, nan, True, 'Matched'), ('VTPLLAHLSSAHLA', 21895, nan, False, 'Matched'), ('TFNHSGISV', 21648, nan, True, 'Matched'), ('ETFPDAKGWIF', 21958, nan, False, 'Matched'), ('TPLLAHLSSAHLA', 21822, nan, True, 'Matched'), ('LSDHLINQGY', 21682, nan, True, 'Matched'), ('SAHLAFMTF', 21860, nan, True, 'Matched'), ('FPALTSLLSQKVRESE', 21842, nan, False, 'Matched'), ('LSDHLINQGY', 21730, nan, True, 'Matched'), ('LSDHLINQGY', 21717, nan, True, 'Matched'), ('VYFPALTSL', 21755, nan, True, 'Matched'), ('FPALTSLLSQKVRESE', 21844, nan, False, 'Matched'), ('TFNHSGISV', 21646, nan, True, 'Matched'), ('RSSMPICTV', 21940, nan, True, 'Matched'), ('TPLLAHLSSAHLA', 21823, nan, True, 'Matched'), ('ETFPDAKGWIF', 21959, nan, False, 'Matched'), ('LSDHLINQGY', 21732, nan, True, 'Matched'), ('RSSMPICTV', 21938, nan, True, 'Matched'), ('LSDHLINQGY', 21733, nan, True, 'Matched'), ('TFNHSGISV', 21657, nan, True, 'Matched'), ('VYFPALTSL', 21742, nan, True, 'Matched'), ('LSDHLINQGY', 21716, nan, True, 'Matched'), ('ETFPDAKGWIF', 21957, nan, False, 'Matched'), ('VTPLLAHLSSAHLA', 21896, nan, False, 'Matched'), ('TPLLAHLSSAHLA', 21814, nan, True, 'Matched'), ('VYFPALTSL', 21741, nan, True, 'Matched'), ('SAHLAFMTF', 21867, nan, True, 'Matched'), ('LSDHLINQGY', 21677, nan, True, 'Matched'), ('TPLLAHLSSAHLA', 21815, nan, True, 'Matched'), ('LSDHLINQGY', 21715, nan, True, 'Matched'), ('FPALTSLLSQKVRESE', 21845, nan, False, 'Matched'), ('LSDHLINQGY', 21734, nan, True, 'Matched'), ('LSDHLINQGY', 21680, nan, True, 'Matched'), ('VYFPALTSL', 21751, nan, True, 'Matched'), ('VYFPALTSL', 21780, nan, True, 'Matched'), ('RSSMPICTV', 21939, nan, True, 'Matched'), ('LSDHLINQGY', 21727, nan, True, 'Matched'), ('VYFPALTSL', 21740, nan, True, 'Matched'), ('VYFPALTSL', 21786, nan, True, 'Matched'), ('LSDHLINQGY', 21697, nan, True, 'Matched'), ('VYFPALTSL', 21798, nan, True, 'Matched'), ('VYFPALTSL', 21797, nan, True, 'Matched'), ('LSDHLINQGY', 21699, nan, True, 'Matched'), ('LSDHLINQGY', 21698, nan, True, 'Matched'), ('LSDHLINQGY', 21690, nan, True, 'Matched'), ('VYFPALTSL', 21790, nan, True, 'Matched'), ('VTPLLAHLSSAHLA', 21890, nan, False, 'Matched'), ('VDLSSTHEDL', 21952, nan, True, 'Matched'), ('LSDHLINQGY', 21736, nan, True, 'Matched'), ('VYFPALTSL', 21746, nan, True, 'Matched'), ('VYFPALTSL', 21782, nan, True, 'Matched'), ('VYFPALTSL', 21788, nan, True, 'Matched'), ('VYFPALTSL', 21783, nan, True, 'Matched'), ('VYFPALTSL', 21743, nan, True, 'Matched'), ('VYFPALTSL', 21749, nan, True, 'Matched'), ('TFNHSGISV', 21625, nan, True, 'Matched'), ('VTPLLAHLSSAHLA', 21894, nan, False, 'Matched'), ('VYFPALTSL', 21781, nan, True, 'Matched'), ('VYFPALTSL', 21753, nan, True, 'Matched'), ('VYFPALTSL', 21784, nan, True, 'Matched'), ('LSDHLINQGY', 21731, nan, True, 'Matched'), ('VYFPALTSL', 21748, nan, True, 'Matched'), ('VYFPALTSL', 21787, nan, True, 'Matched'), ('VYFPALTSL', 21791, nan, True, 'Matched'), ('VYFPALTSL', 21747, nan, True, 'Matched'), ('VYFPALTSL', 21792, nan, True, 'Matched'), ('VYFPALTSL', 21789, nan, True, 'Matched'), ('VYFPALTSL', 21778, nan, True, 'Matched'), ('VYFPALTSL', 21757, nan, True, 'Matched'), ('VYFPALTSL', 21779, nan, True, 'Matched'), ('VYFPALTSL', 21794, nan, True, 'Matched'), ('TPLLAHLSSAHLA', 21819, nan, True, 'Matched'), ('VYFPALTSL', 21750, nan, True, 'Matched'), ('VYFPALTSL', 21795, nan, True, 'Matched'), ('VYFPALTSL', 21745, nan, True, 'Matched'), ('KVRESERAF', 21964, nan, True, 'Matched'), ('VYFPALTSL', 21752, nan, True, 'Matched'), ('VYFPALTSL', 21785, nan, True, 'Matched'), ('FPALTSLLSQKVRESE', 21830, nan, False, 'Matched'), ('KVRESERAF', 21965, nan, True, 'Matched'), ('TPLLAHLSSAHLA', 21817, nan, True, 'Matched'), ('VYFPALTSL', 21754, nan, True, 'Matched'), ('LSDHLINQGY', 21676, nan, True, 'Matched'), ('RSSMPICTV', 21937, nan, True, 'Matched'), ('VYFPALTSL', 21796, nan, True, 'Matched'), ('VYFPALTSL', 21756, nan, True, 'Matched'), ('VTPLLAHLSSAHLA', 21893, nan, False, 'Matched'), ('FRKPAVWAA', 21906, nan, True, 'Matched'), ('VYFPALTSL', 21744, nan, True, 'Matched'), ('TPLLAHLSSAHLA', 21824, nan, True, 'Matched'), ('KPAVWAAVVSQLSAA', 21946, nan, True, 'Matched'), ('KPAVWAAVVSQLSAA', 21944, nan, True, 'Matched'), ('KPAVWAAVVSQLSAA', 21945, nan, True, 'Matched'), ('KPAVWAAVVSQLSAA', 21943, nan, True, 'Matched'), ('VTPLLAHLSSAHLA', 21900, nan, False, 'Matched'), ('VTPLLAHLSSAHLA', 21891, nan, False, 'Matched'), ('FRKPAVWAA', 21904, nan, True, 'Matched'), ('FRKPAVWAA', 21908, nan, True, 'Matched'), ('VTPLLAHLSSAHLA', 21897, nan, False, 'Matched'), ('FRKPAVWAA', 21909, nan, True, 'Matched'), ('FRKPAVWAA', 21902, nan, True, 'Matched'), ('FRKPAVWAA', 21901, nan, True, 'Matched'), ('FRKPAVWAA', 21907, nan, True, 'Matched'), ('TPLLAHLSSAHLAF', 21967, nan, False, 'Matched'), ('FRKPAVWAA', 21903, nan, True, 'Matched'), ('FRKPAVWAA', 21910, nan, True, 'Matched')] | I4: 18 | J4: =IFERROR(VLOOKUP(A4,dbg_proteins!$A$2:$A$20161,1,FALSE)," ---") -> Q9BYT1
